<?xml version="1.0" ?>
<!-- =================================================================================== -->
<!-- |    This document was autogenerated by xacro from panda_arm_hand.urdf.xacro      | -->
<!-- |    EDITING THIS FILE BY HAND IS NOT RECOMMENDED                                 | -->
<!-- =================================================================================== -->
<robot name="panda" xmlns:xacro="http://www.ros.org/wiki/xacro">
  <link name="panda_link0">
  	<inertial>
      <origin rpy="0 0 0" xyz="0 0 0.05"/>
      <mass value="2.9"/>
      <inertia ixx="0.1" ixy="0" ixz="0" iyy="0.1" iyz="0" izz="0.1"/>
    </inertial>
    <visual>
      <geometry>
        <mesh filename="package://meshes/collision/link0.obj"/>
      </geometry>
      <material name="panda_white">
    		<color rgba="1. 1. 1. 1."/>
  		</material>
    </visual>
    <collision>
      <geometry>
        <mesh filename="package://meshes/collision/link0.obj"/>
      </geometry>
      <material name="panda_white"/>
    </collision>
  </link>
  <link name="panda_link1">
  	<inertial>
      <origin rpy="0 0 0" xyz="0 -0.04 -0.05"/>
      <mass value="2.7"/>
      <inertia ixx="0.1" ixy="0" ixz="0" iyy="0.1" iyz="0" izz="0.1"/>
    </inertial>
    <visual>
      <geometry>
        <mesh filename="package://meshes/visual/link1.obj"/>
      </geometry>
      <material name="panda_white"/>
    </visual>
    <collision>
      <geometry>
        <mesh filename="package://meshes/collision/link1.obj"/>
      </geometry>
      <material name="panda_white"/>
    </collision>
  </link>
  <joint name="panda_joint1" type="revolute">
    <safety_controller k_position="100.0" k_velocity="40.0" soft_lower_limit="-2.8973" soft_upper_limit="2.8973"/>
    <origin rpy="0 0 0" xyz="0 0 0.333"/>
    <parent link="panda_link0"/>
    <child link="panda_link1"/>
    <axis xyz="0 0 1"/>
    <limit effort="87" lower="-6.2831853" upper="6.2831853" velocity="2.1750"/>
  </joint>
  <link name="panda_link2">
  	<inertial>
      <origin rpy="0 0 0" xyz="0 -0.04 0.06"/>
      <mass value="2.73"/>
      <inertia ixx="0.1" ixy="0" ixz="0" iyy="0.1" iyz="0" izz="0.1"/>
    </inertial>
    <visual>
      <geometry>
        <mesh filename="package://meshes/visual/link2.obj"/>
      </geometry>
      <material name="panda_white"/>
    </visual>
    <collision>
      <geometry>
        <mesh filename="package://meshes/collision/link2.obj"/>
      </geometry>
      <material name="panda_white"/>
    </collision>
  </link>
  <joint name="panda_joint2" type="revolute">
    <safety_controller k_position="100.0" k_velocity="40.0" soft_lower_limit="-1.7628" soft_upper_limit="1.7628"/>
    <origin rpy="-1.57079632679 0 0" xyz="0 0 0"/>
    <parent link="panda_link1"/>
    <child link="panda_link2"/>
    <axis xyz="0 0 1"/>
    <limit effort="87" lower="-6.2831853" upper="6.2831853" velocity="2.1750"/>
  </joint>
  <link name="panda_link3">
	  <inertial>
      <origin rpy="0 0 0" xyz="0.01 0.01 -0.05"/>
      <mass value="2.04"/>
      <inertia ixx="0.1" ixy="0" ixz="0" iyy="0.1" iyz="0" izz="0.1"/>
    </inertial>
    <visual>
      <geometry>
        <mesh filename="package://meshes/visual/link3.obj"/>
      </geometry>
      <material name="panda_red">
    		<color rgba="1. 1. 1. 1."/>
  		</material>
    </visual>
    <collision>
      <geometry>
        <mesh filename="package://meshes/collision/link3.obj"/>
      </geometry>
    </collision>
  </link>
  <joint name="panda_joint3" type="revolute">
    <safety_controller k_position="100.0" k_velocity="40.0" soft_lower_limit="-2.8973" soft_upper_limit="2.8973"/>
    <origin rpy="1.57079632679 0 0" xyz="0 -0.316 0"/>
    <parent link="panda_link2"/>
    <child link="panda_link3"/>
    <axis xyz="0 0 1"/>
    <limit effort="87" lower="-6.2831853" upper="6.2831853" velocity="2.1750"/>
  </joint>
  <link name="panda_link4">
  	<inertial>
      <origin rpy="0 0 0" xyz="-0.03 0.03 0.02"/>
      <mass value="2.08"/>
      <inertia ixx="0.1" ixy="0" ixz="0" iyy="0.1" iyz="0" izz="0.1"/>
    </inertial>
    <visual>
      <geometry>
        <mesh filename="package://meshes/visual/link4.obj"/>
      </geometry>
      <material name="panda_white"/>
    </visual>
    <collision>
      <geometry>
        <mesh filename="package://meshes/collision/link4.obj"/>
      </geometry>
      <material name="panda_white"/>
    </collision>
  </link>
  <joint name="panda_joint4" type="revolute">
    <safety_controller k_position="100.0" k_velocity="40.0" soft_lower_limit="-3.0718" soft_upper_limit="-0.0698"/>
    <origin rpy="1.57079632679 0 0" xyz="0.0825 0 0"/>
    <parent link="panda_link3"/>
    <child link="panda_link4"/>
    <axis xyz="0 0 1"/>
    <limit effort="87" lower="-6.2831853" upper="6.2831853" velocity="2.1750"/>
  </joint>
  <link name="panda_link5">
  	<inertial>
      <origin rpy="0 0 0" xyz="0 0.04 -0.12"/>
      <mass value="3"/>
      <inertia ixx="0.1" ixy="0" ixz="0" iyy="0.1" iyz="0" izz="0.1"/>
    </inertial>
    <visual>
      <geometry>
        <mesh filename="package://meshes/visual/link5.obj"/>
      </geometry>
      <material name="panda_white"/>
    </visual>
    <collision>
      <geometry>
        <mesh filename="package://meshes/collision/link5.obj"/>
      </geometry>
      <material name="panda_white"/>
    </collision>
  </link>
  <joint name="panda_joint5" type="revolute">
    <safety_controller k_position="100.0" k_velocity="40.0" soft_lower_limit="-2.8973" soft_upper_limit="2.8973"/>
    <origin rpy="-1.57079632679 0 0" xyz="-0.0825 0.384 0"/>
    <parent link="panda_link4"/>
    <child link="panda_link5"/>
    <axis xyz="0 0 1"/>
    <limit effort="12" lower="-6.2831853" upper="6.2831853" velocity="2.6100"/>
  </joint>
  <link name="panda_link6">
  	<inertial>
      <origin rpy="0 0 0" xyz="0.04 0 0"/>
      <mass value="1.3"/>
      <inertia ixx="0.1" ixy="0" ixz="0" iyy="0.1" iyz="0" izz="0.1"/>
    </inertial>
    <visual>
      <geometry>
        <mesh filename="package://meshes/visual/link6.obj"/>
      </geometry>
      <material name="panda_white"/>
    </visual>
    <collision>
      <geometry>
        <mesh filename="package://meshes/collision/link6.obj"/>
      </geometry>
      <material name="panda_white"/>
    </collision>
  </link>
  <joint name="panda_joint6" type="revolute">
    <safety_controller k_position="100.0" k_velocity="40.0" soft_lower_limit="-0.0175" soft_upper_limit="3.7525"/>
    <origin rpy="1.57079632679 0 0" xyz="0 0 0"/>
    <parent link="panda_link5"/>
    <child link="panda_link6"/>
    <axis xyz="0 0 1"/>
    <limit effort="12" lower="-6.2831853" upper="6.2831853" velocity="2.6100"/>
  </joint>
  <link name="panda_link7">
  	<inertial>
      <origin rpy="0 0 0" xyz="0 0 0.08"/>
      <mass value=".2"/>
      <inertia ixx="0.1" ixy="0" ixz="0" iyy="0.1" iyz="0" izz="0.1"/>
    </inertial>
    <visual>
      <geometry>
        <mesh filename="package://meshes/collision/link7.obj"/>
      </geometry>
      <material name="panda_white"/>
    </visual>
    <collision>
      <geometry>
        <mesh filename="package://meshes/collision/link7.obj"/>
      </geometry>
      <material name="panda_white"/>
    </collision>
  </link>
  <joint name="panda_joint7" type="revolute">
    <safety_controller k_position="100.0" k_velocity="40.0" soft_lower_limit="-2.8973" soft_upper_limit="2.8973"/>
    <origin rpy="1.57079632679 0 0" xyz="0.088 0 0"/>
    <parent link="panda_link6"/>
    <child link="panda_link7"/>
    <axis xyz="0 0 1"/>
    <limit effort="12" lower="-6.2831853" upper="6.2831853" velocity="2.6100"/>
  </joint>
  <link name="panda_link8">
  	 <inertial>
      <origin rpy="0 0 0" xyz="0 0 0"/>
      <mass value="0.0"/>
      <inertia ixx="0.1" ixy="0" ixz="0" iyy="0.1" iyz="0" izz="0.1"/>
    </inertial>
  </link>
  <joint name="panda_joint8" type="fixed">
    <origin rpy="0 0 0" xyz="0 0 0.107"/>
    <parent link="panda_link7"/>
    <child link="panda_link8"/>
    <axis xyz="0 0 0"/>
  </joint>
  
  <!--My Panda-->
  <link name="panda_tool">
  	<inertial>
      <origin rpy="0 0 0" xyz="0 0 0"/>
      <mass value="0.01"/>
      <inertia ixx="0.01" ixy="0.01" ixz="0.0" iyy="0.01" iyz="0.01" izz="0.01"/>
    </inertial>
    <visual>
      <geometry>
        <mesh filename="package://meshes/ffc_assembly/tool.obj"/>
      </geometry>
      <material name="panda_white"/>
    </visual>
    <collision>
      <geometry>
        <mesh filename="package://meshes/ffc_assembly/tool.obj"/>
      </geometry>
      <material name="panda_white"/>
    </collision>
  </link>
  <joint name="panda_tool_joint" type="fixed">
    <parent link="panda_link8"/>
    <child link="panda_tool"/>
    <origin rpy="-1.57079632679 0 1.57079632679" xyz="0 0 0"/>
  </joint>

  <link name="panda_ee">
    <inertial>
      <origin rpy="0 0 0" xyz="0 0 0"/>
      <mass value="0.0"/>
      <inertia ixx="0.0" ixy="0.0" ixz="0.0" iyy="0.0" iyz="0.0" izz="0.0"/>
    </inertial>
  </link>
  <joint name="panda_ee_joint" type="fixed">
    <parent link="panda_tool"/>
    <child link="panda_ee"/>
    <!--<origin xyz="0 0.086 -0.0368" rpy="0 1.57079632679 -1.57079632679"/>-->
    <origin xyz="0 -0.0305 -0.086" rpy="0 1.57079632679 -1.57079632679"/>
  </joint>


  <!--flexible flat cable-->

  <link name="ffc_model">
    <inertial>
      <origin rpy="0 0 0" xyz="0 0 0"/>
      <mass value="0.01"/>
      <inertia ixx="0.0" ixy="0.0" ixz="0.0" iyy="0.0" iyz="0.0" izz="0.0"/>
    </inertial>
    <visual>
      <geometry>
        <mesh filename="package://meshes/ffc_assembly/ffc.obj"/>
      </geometry>
      <material name="panda_white"/>
    </visual>
    <collision>
      <geometry>
        <mesh filename="package://meshes/ffc_assembly/ffc.obj"/>
      </geometry>
      <material name="panda_white"/>
    </collision>
  </link>

  <joint name="ffc_joint" type="fixed">
    <parent link="panda_ee"/>
    <child link="ffc_model"/>
    <origin xyz="-0.0492 0 0" rpy="1.57079632679 0 1.57079632679"/>
  </joint>


</robot>
